{
 "cells": [
  {
   "cell_type": "code",
   "execution_count": 1,
   "metadata": {},
   "outputs": [],
   "source": [
    "from src import meliRetriever, getAPIkey"
   ]
  },
  {
   "cell_type": "code",
   "execution_count": 2,
   "metadata": {},
   "outputs": [
    {
     "name": "stdout",
     "output_type": "stream",
     "text": [
      "https://www.mercadolibre.com/jms/mco/lgz/login/?go=https%3A%2F%2Fauth.mercadolibre.com.co%2Fauthorization%3Fclient_id%3D4892726125387151%26redirect_uri%3Dhttps%253A%252F%252Fwww.mercadolibre.com.co%252F%26response_type%3Dcode&platform_id=ml&application_id=4892726125387151\n",
      "Please write the code:········\n"
     ]
    }
   ],
   "source": [
    "get_token = getAPIkey()"
   ]
  },
  {
   "cell_type": "code",
   "execution_count": 3,
   "metadata": {},
   "outputs": [],
   "source": [
    "dff = meliRetriever(site_name = 'Colombia', token = get_token.api_key)"
   ]
  },
  {
   "cell_type": "code",
   "execution_count": null,
   "metadata": {
    "scrolled": true
   },
   "outputs": [
    {
     "name": "stderr",
     "output_type": "stream",
     "text": [
      "  6% (2 of 31) |#                | Elapsed Time: 4:44:31 ETA:  2 days, 10:42:56ERROR:root:Internal Python error in the inspect module.\n",
      "Below is the traceback from this internal error.\n",
      "\n",
      "ERROR:root:Internal Python error in the inspect module.\n",
      "Below is the traceback from this internal error.\n",
      "\n"
     ]
    },
    {
     "name": "stdout",
     "output_type": "stream",
     "text": [
      "Traceback (most recent call last):\n",
      "  File \"c:\\users\\juan\\appdata\\local\\programs\\python\\python38-32\\lib\\site-packages\\IPython\\core\\interactiveshell.py\", line 3417, in run_code\n",
      "    exec(code_obj, self.user_global_ns, self.user_ns)\n",
      "  File \"<ipython-input-4-0901c54d1491>\", line 1, in <module>\n",
      "    tmp_df = dff.create_dataset(file_name = 'data/ColombianData.csv')\n",
      "  File \"C:\\Users\\Juan\\MeliDSChallenge\\src\\retrieve.py\", line 45, in create_dataset\n",
      "    category_dataframes = [self.iterate_through_category(self.site_id, category_id, export_individual, check_existence)\n",
      "  File \"C:\\Users\\Juan\\MeliDSChallenge\\src\\retrieve.py\", line 45, in <listcomp>\n",
      "    category_dataframes = [self.iterate_through_category(self.site_id, category_id, export_individual, check_existence)\n",
      "  File \"C:\\Users\\Juan\\MeliDSChallenge\\src\\retrieve.py\", line 155, in iterate_through_category\n",
      "    complete_category_df = pd.read_csv(path, sep = \";\")\n",
      "  File \"C:\\Users\\Juan\\MeliDSChallenge\\src\\retrieve.py\", line 155, in <listcomp>\n",
      "    complete_category_df = pd.read_csv(path, sep = \";\")\n",
      "  File \"C:\\Users\\Juan\\MeliDSChallenge\\src\\retrieve.py\", line 124, in list_marketplace_products\n",
      "  File \"C:\\Users\\Juan\\MeliDSChallenge\\src\\retrieve.py\", line 187, in multiple_attribute_keys_df\n",
      "    seller_attributes = self.iterate_and_combine(product_json, self.extract_seller_attributes)\n",
      "  File \"C:\\Users\\Juan\\MeliDSChallenge\\src\\retrieve.py\", line 215, in iterate_and_combine\n",
      "  File \"C:\\Users\\Juan\\MeliDSChallenge\\src\\retrieve.py\", line 215, in <listcomp>\n",
      "  File \"C:\\Users\\Juan\\MeliDSChallenge\\src\\retrieve.py\", line 320, in retrieve_date_and_questions\n",
      "    time.sleep(0.5)\n",
      "  File \"c:\\users\\juan\\appdata\\local\\programs\\python\\python38-32\\lib\\site-packages\\requests\\api.py\", line 76, in get\n",
      "    return request('get', url, params=params, **kwargs)\n",
      "  File \"c:\\users\\juan\\appdata\\local\\programs\\python\\python38-32\\lib\\site-packages\\requests\\api.py\", line 61, in request\n",
      "    return session.request(method=method, url=url, **kwargs)\n",
      "  File \"c:\\users\\juan\\appdata\\local\\programs\\python\\python38-32\\lib\\site-packages\\requests\\sessions.py\", line 530, in request\n",
      "    resp = self.send(prep, **send_kwargs)\n",
      "  File \"c:\\users\\juan\\appdata\\local\\programs\\python\\python38-32\\lib\\site-packages\\requests\\sessions.py\", line 643, in send\n",
      "    r = adapter.send(request, **kwargs)\n",
      "  File \"c:\\users\\juan\\appdata\\local\\programs\\python\\python38-32\\lib\\site-packages\\requests\\adapters.py\", line 439, in send\n",
      "    resp = conn.urlopen(\n",
      "  File \"c:\\users\\juan\\appdata\\local\\programs\\python\\python38-32\\lib\\site-packages\\urllib3\\connectionpool.py\", line 670, in urlopen\n",
      "    httplib_response = self._make_request(\n",
      "  File \"c:\\users\\juan\\appdata\\local\\programs\\python\\python38-32\\lib\\site-packages\\urllib3\\connectionpool.py\", line 426, in _make_request\n",
      "    six.raise_from(e, None)\n",
      "  File \"<string>\", line 3, in raise_from\n",
      "  File \"c:\\users\\juan\\appdata\\local\\programs\\python\\python38-32\\lib\\site-packages\\urllib3\\connectionpool.py\", line 421, in _make_request\n",
      "    httplib_response = conn.getresponse()\n",
      "  File \"c:\\users\\juan\\appdata\\local\\programs\\python\\python38-32\\lib\\http\\client.py\", line 1347, in getresponse\n",
      "    response.begin()\n",
      "  File \"c:\\users\\juan\\appdata\\local\\programs\\python\\python38-32\\lib\\http\\client.py\", line 307, in begin\n",
      "    version, status, reason = self._read_status()\n",
      "  File \"c:\\users\\juan\\appdata\\local\\programs\\python\\python38-32\\lib\\http\\client.py\", line 268, in _read_status\n",
      "    line = str(self.fp.readline(_MAXLINE + 1), \"iso-8859-1\")\n",
      "  File \"c:\\users\\juan\\appdata\\local\\programs\\python\\python38-32\\lib\\socket.py\", line 669, in readinto\n",
      "    return self._sock.recv_into(b)\n",
      "  File \"c:\\users\\juan\\appdata\\local\\programs\\python\\python38-32\\lib\\ssl.py\", line 1241, in recv_into\n",
      "    return self.read(nbytes, buffer)\n",
      "  File \"c:\\users\\juan\\appdata\\local\\programs\\python\\python38-32\\lib\\ssl.py\", line 1099, in read\n",
      "    return self._sslobj.read(len, buffer)\n",
      "KeyboardInterrupt\n",
      "\n",
      "During handling of the above exception, another exception occurred:\n",
      "\n",
      "Traceback (most recent call last):\n",
      "  File \"c:\\users\\juan\\appdata\\local\\programs\\python\\python38-32\\lib\\site-packages\\IPython\\core\\interactiveshell.py\", line 2044, in showtraceback\n",
      "    stb = value._render_traceback_()\n",
      "AttributeError: 'KeyboardInterrupt' object has no attribute '_render_traceback_'\n",
      "\n",
      "During handling of the above exception, another exception occurred:\n",
      "\n",
      "Traceback (most recent call last):\n",
      "  File \"c:\\users\\juan\\appdata\\local\\programs\\python\\python38-32\\lib\\site-packages\\IPython\\core\\ultratb.py\", line 1169, in get_records\n",
      "    return _fixed_getinnerframes(etb, number_of_lines_of_context, tb_offset)\n",
      "  File \"c:\\users\\juan\\appdata\\local\\programs\\python\\python38-32\\lib\\site-packages\\IPython\\core\\ultratb.py\", line 316, in wrapped\n",
      "    return f(*args, **kwargs)\n",
      "  File \"c:\\users\\juan\\appdata\\local\\programs\\python\\python38-32\\lib\\site-packages\\IPython\\core\\ultratb.py\", line 350, in _fixed_getinnerframes\n",
      "    records = fix_frame_records_filenames(inspect.getinnerframes(etb, context))\n",
      "  File \"c:\\users\\juan\\appdata\\local\\programs\\python\\python38-32\\lib\\inspect.py\", line 1503, in getinnerframes\n",
      "    frameinfo = (tb.tb_frame,) + getframeinfo(tb, context)\n",
      "  File \"c:\\users\\juan\\appdata\\local\\programs\\python\\python38-32\\lib\\inspect.py\", line 1461, in getframeinfo\n",
      "    filename = getsourcefile(frame) or getfile(frame)\n",
      "  File \"c:\\users\\juan\\appdata\\local\\programs\\python\\python38-32\\lib\\inspect.py\", line 708, in getsourcefile\n",
      "    if getattr(getmodule(object, filename), '__loader__', None) is not None:\n",
      "  File \"c:\\users\\juan\\appdata\\local\\programs\\python\\python38-32\\lib\\inspect.py\", line 754, in getmodule\n",
      "    os.path.realpath(f)] = module.__name__\n",
      "  File \"c:\\users\\juan\\appdata\\local\\programs\\python\\python38-32\\lib\\ntpath.py\", line 664, in realpath\n",
      "    if _getfinalpathname(spath) == path:\n",
      "KeyboardInterrupt\n",
      "Traceback (most recent call last):\n",
      "  File \"c:\\users\\juan\\appdata\\local\\programs\\python\\python38-32\\lib\\site-packages\\IPython\\core\\interactiveshell.py\", line 3417, in run_code\n",
      "    exec(code_obj, self.user_global_ns, self.user_ns)\n",
      "  File \"<ipython-input-4-0901c54d1491>\", line 1, in <module>\n",
      "    tmp_df = dff.create_dataset(file_name = 'data/ColombianData.csv')\n",
      "  File \"C:\\Users\\Juan\\MeliDSChallenge\\src\\retrieve.py\", line 45, in create_dataset\n",
      "    category_dataframes = [self.iterate_through_category(self.site_id, category_id, export_individual, check_existence)\n",
      "  File \"C:\\Users\\Juan\\MeliDSChallenge\\src\\retrieve.py\", line 45, in <listcomp>\n",
      "    category_dataframes = [self.iterate_through_category(self.site_id, category_id, export_individual, check_existence)\n",
      "  File \"C:\\Users\\Juan\\MeliDSChallenge\\src\\retrieve.py\", line 155, in iterate_through_category\n",
      "    complete_category_df = pd.read_csv(path, sep = \";\")\n",
      "  File \"C:\\Users\\Juan\\MeliDSChallenge\\src\\retrieve.py\", line 155, in <listcomp>\n",
      "    complete_category_df = pd.read_csv(path, sep = \";\")\n",
      "  File \"C:\\Users\\Juan\\MeliDSChallenge\\src\\retrieve.py\", line 124, in list_marketplace_products\n",
      "  File \"C:\\Users\\Juan\\MeliDSChallenge\\src\\retrieve.py\", line 187, in multiple_attribute_keys_df\n",
      "    seller_attributes = self.iterate_and_combine(product_json, self.extract_seller_attributes)\n",
      "  File \"C:\\Users\\Juan\\MeliDSChallenge\\src\\retrieve.py\", line 215, in iterate_and_combine\n",
      "  File \"C:\\Users\\Juan\\MeliDSChallenge\\src\\retrieve.py\", line 215, in <listcomp>\n",
      "  File \"C:\\Users\\Juan\\MeliDSChallenge\\src\\retrieve.py\", line 320, in retrieve_date_and_questions\n",
      "    time.sleep(0.5)\n",
      "  File \"c:\\users\\juan\\appdata\\local\\programs\\python\\python38-32\\lib\\site-packages\\requests\\api.py\", line 76, in get\n",
      "    return request('get', url, params=params, **kwargs)\n",
      "  File \"c:\\users\\juan\\appdata\\local\\programs\\python\\python38-32\\lib\\site-packages\\requests\\api.py\", line 61, in request\n",
      "    return session.request(method=method, url=url, **kwargs)\n",
      "  File \"c:\\users\\juan\\appdata\\local\\programs\\python\\python38-32\\lib\\site-packages\\requests\\sessions.py\", line 530, in request\n",
      "    resp = self.send(prep, **send_kwargs)\n",
      "  File \"c:\\users\\juan\\appdata\\local\\programs\\python\\python38-32\\lib\\site-packages\\requests\\sessions.py\", line 643, in send\n",
      "    r = adapter.send(request, **kwargs)\n",
      "  File \"c:\\users\\juan\\appdata\\local\\programs\\python\\python38-32\\lib\\site-packages\\requests\\adapters.py\", line 439, in send\n",
      "    resp = conn.urlopen(\n",
      "  File \"c:\\users\\juan\\appdata\\local\\programs\\python\\python38-32\\lib\\site-packages\\urllib3\\connectionpool.py\", line 670, in urlopen\n",
      "    httplib_response = self._make_request(\n",
      "  File \"c:\\users\\juan\\appdata\\local\\programs\\python\\python38-32\\lib\\site-packages\\urllib3\\connectionpool.py\", line 426, in _make_request\n",
      "    six.raise_from(e, None)\n",
      "  File \"<string>\", line 3, in raise_from\n",
      "  File \"c:\\users\\juan\\appdata\\local\\programs\\python\\python38-32\\lib\\site-packages\\urllib3\\connectionpool.py\", line 421, in _make_request\n",
      "    httplib_response = conn.getresponse()\n",
      "  File \"c:\\users\\juan\\appdata\\local\\programs\\python\\python38-32\\lib\\http\\client.py\", line 1347, in getresponse\n",
      "    response.begin()\n",
      "  File \"c:\\users\\juan\\appdata\\local\\programs\\python\\python38-32\\lib\\http\\client.py\", line 307, in begin\n",
      "    version, status, reason = self._read_status()\n",
      "  File \"c:\\users\\juan\\appdata\\local\\programs\\python\\python38-32\\lib\\http\\client.py\", line 268, in _read_status\n",
      "    line = str(self.fp.readline(_MAXLINE + 1), \"iso-8859-1\")\n",
      "  File \"c:\\users\\juan\\appdata\\local\\programs\\python\\python38-32\\lib\\socket.py\", line 669, in readinto\n",
      "    return self._sock.recv_into(b)\n",
      "  File \"c:\\users\\juan\\appdata\\local\\programs\\python\\python38-32\\lib\\ssl.py\", line 1241, in recv_into\n",
      "    return self.read(nbytes, buffer)\n",
      "  File \"c:\\users\\juan\\appdata\\local\\programs\\python\\python38-32\\lib\\ssl.py\", line 1099, in read\n",
      "    return self._sslobj.read(len, buffer)\n",
      "KeyboardInterrupt\n",
      "\n",
      "During handling of the above exception, another exception occurred:\n",
      "\n",
      "Traceback (most recent call last):\n",
      "  File \"c:\\users\\juan\\appdata\\local\\programs\\python\\python38-32\\lib\\site-packages\\IPython\\core\\interactiveshell.py\", line 2044, in showtraceback\n",
      "    stb = value._render_traceback_()\n",
      "AttributeError: 'KeyboardInterrupt' object has no attribute '_render_traceback_'\n",
      "\n",
      "During handling of the above exception, another exception occurred:\n",
      "\n",
      "Traceback (most recent call last):\n",
      "  File \"c:\\users\\juan\\appdata\\local\\programs\\python\\python38-32\\lib\\site-packages\\IPython\\core\\interactiveshell.py\", line 3337, in run_ast_nodes\n",
      "    if (await self.run_code(code, result,  async_=asy)):\n",
      "  File \"c:\\users\\juan\\appdata\\local\\programs\\python\\python38-32\\lib\\site-packages\\IPython\\core\\interactiveshell.py\", line 3434, in run_code\n",
      "    self.showtraceback(running_compiled_code=True)\n",
      "  File \"c:\\users\\juan\\appdata\\local\\programs\\python\\python38-32\\lib\\site-packages\\IPython\\core\\interactiveshell.py\", line 2046, in showtraceback\n",
      "    stb = self.InteractiveTB.structured_traceback(etype,\n",
      "  File \"c:\\users\\juan\\appdata\\local\\programs\\python\\python38-32\\lib\\site-packages\\IPython\\core\\ultratb.py\", line 1435, in structured_traceback\n",
      "    return FormattedTB.structured_traceback(\n",
      "  File \"c:\\users\\juan\\appdata\\local\\programs\\python\\python38-32\\lib\\site-packages\\IPython\\core\\ultratb.py\", line 1335, in structured_traceback\n",
      "    return VerboseTB.structured_traceback(\n",
      "  File \"c:\\users\\juan\\appdata\\local\\programs\\python\\python38-32\\lib\\site-packages\\IPython\\core\\ultratb.py\", line 1192, in structured_traceback\n",
      "    formatted_exception = self.format_exception_as_a_whole(etype, evalue, etb, number_of_lines_of_context,\n",
      "  File \"c:\\users\\juan\\appdata\\local\\programs\\python\\python38-32\\lib\\site-packages\\IPython\\core\\ultratb.py\", line 1150, in format_exception_as_a_whole\n",
      "    last_unique, recursion_repeat = find_recursion(orig_etype, evalue, records)\n",
      "  File \"c:\\users\\juan\\appdata\\local\\programs\\python\\python38-32\\lib\\site-packages\\IPython\\core\\ultratb.py\", line 451, in find_recursion\n",
      "    return len(records), 0\n",
      "TypeError: object of type 'NoneType' has no len()\n",
      "\n",
      "During handling of the above exception, another exception occurred:\n",
      "\n",
      "Traceback (most recent call last):\n",
      "  File \"c:\\users\\juan\\appdata\\local\\programs\\python\\python38-32\\lib\\site-packages\\IPython\\core\\interactiveshell.py\", line 2044, in showtraceback\n",
      "    stb = value._render_traceback_()\n",
      "AttributeError: 'TypeError' object has no attribute '_render_traceback_'\n",
      "\n",
      "During handling of the above exception, another exception occurred:\n",
      "\n",
      "Traceback (most recent call last):\n",
      "  File \"c:\\users\\juan\\appdata\\local\\programs\\python\\python38-32\\lib\\site-packages\\IPython\\core\\ultratb.py\", line 1169, in get_records\n",
      "    return _fixed_getinnerframes(etb, number_of_lines_of_context, tb_offset)\n",
      "  File \"c:\\users\\juan\\appdata\\local\\programs\\python\\python38-32\\lib\\site-packages\\IPython\\core\\ultratb.py\", line 316, in wrapped\n",
      "    return f(*args, **kwargs)\n",
      "  File \"c:\\users\\juan\\appdata\\local\\programs\\python\\python38-32\\lib\\site-packages\\IPython\\core\\ultratb.py\", line 350, in _fixed_getinnerframes\n",
      "    records = fix_frame_records_filenames(inspect.getinnerframes(etb, context))\n",
      "  File \"c:\\users\\juan\\appdata\\local\\programs\\python\\python38-32\\lib\\inspect.py\", line 1503, in getinnerframes\n",
      "    frameinfo = (tb.tb_frame,) + getframeinfo(tb, context)\n",
      "  File \"c:\\users\\juan\\appdata\\local\\programs\\python\\python38-32\\lib\\inspect.py\", line 1461, in getframeinfo\n",
      "    filename = getsourcefile(frame) or getfile(frame)\n",
      "  File \"c:\\users\\juan\\appdata\\local\\programs\\python\\python38-32\\lib\\inspect.py\", line 708, in getsourcefile\n",
      "    if getattr(getmodule(object, filename), '__loader__', None) is not None:\n",
      "  File \"c:\\users\\juan\\appdata\\local\\programs\\python\\python38-32\\lib\\inspect.py\", line 751, in getmodule\n",
      "    f = getabsfile(module)\n",
      "  File \"c:\\users\\juan\\appdata\\local\\programs\\python\\python38-32\\lib\\inspect.py\", line 720, in getabsfile\n",
      "    _filename = getsourcefile(object) or getfile(object)\n",
      "  File \"c:\\users\\juan\\appdata\\local\\programs\\python\\python38-32\\lib\\inspect.py\", line 705, in getsourcefile\n",
      "    if os.path.exists(filename):\n",
      "  File \"c:\\users\\juan\\appdata\\local\\programs\\python\\python38-32\\lib\\genericpath.py\", line 19, in exists\n",
      "    os.stat(path)\n",
      "KeyboardInterrupt\n"
     ]
    },
    {
     "name": "stderr",
     "output_type": "stream",
     "text": [
      "ERROR:root:Internal Python error in the inspect module.\n",
      "Below is the traceback from this internal error.\n",
      "\n"
     ]
    },
    {
     "name": "stdout",
     "output_type": "stream",
     "text": [
      "Traceback (most recent call last):\n",
      "  File \"c:\\users\\juan\\appdata\\local\\programs\\python\\python38-32\\lib\\site-packages\\IPython\\core\\interactiveshell.py\", line 3417, in run_code\n",
      "    exec(code_obj, self.user_global_ns, self.user_ns)\n",
      "  File \"<ipython-input-4-0901c54d1491>\", line 1, in <module>\n",
      "    tmp_df = dff.create_dataset(file_name = 'data/ColombianData.csv')\n",
      "  File \"C:\\Users\\Juan\\MeliDSChallenge\\src\\retrieve.py\", line 45, in create_dataset\n",
      "    category_dataframes = [self.iterate_through_category(self.site_id, category_id, export_individual, check_existence)\n",
      "  File \"C:\\Users\\Juan\\MeliDSChallenge\\src\\retrieve.py\", line 45, in <listcomp>\n",
      "    category_dataframes = [self.iterate_through_category(self.site_id, category_id, export_individual, check_existence)\n",
      "  File \"C:\\Users\\Juan\\MeliDSChallenge\\src\\retrieve.py\", line 155, in iterate_through_category\n",
      "    complete_category_df = pd.read_csv(path, sep = \";\")\n",
      "  File \"C:\\Users\\Juan\\MeliDSChallenge\\src\\retrieve.py\", line 155, in <listcomp>\n",
      "    complete_category_df = pd.read_csv(path, sep = \";\")\n",
      "  File \"C:\\Users\\Juan\\MeliDSChallenge\\src\\retrieve.py\", line 124, in list_marketplace_products\n",
      "  File \"C:\\Users\\Juan\\MeliDSChallenge\\src\\retrieve.py\", line 187, in multiple_attribute_keys_df\n",
      "    seller_attributes = self.iterate_and_combine(product_json, self.extract_seller_attributes)\n",
      "  File \"C:\\Users\\Juan\\MeliDSChallenge\\src\\retrieve.py\", line 215, in iterate_and_combine\n",
      "  File \"C:\\Users\\Juan\\MeliDSChallenge\\src\\retrieve.py\", line 215, in <listcomp>\n",
      "  File \"C:\\Users\\Juan\\MeliDSChallenge\\src\\retrieve.py\", line 320, in retrieve_date_and_questions\n",
      "    time.sleep(0.5)\n",
      "  File \"c:\\users\\juan\\appdata\\local\\programs\\python\\python38-32\\lib\\site-packages\\requests\\api.py\", line 76, in get\n",
      "    return request('get', url, params=params, **kwargs)\n",
      "  File \"c:\\users\\juan\\appdata\\local\\programs\\python\\python38-32\\lib\\site-packages\\requests\\api.py\", line 61, in request\n",
      "    return session.request(method=method, url=url, **kwargs)\n",
      "  File \"c:\\users\\juan\\appdata\\local\\programs\\python\\python38-32\\lib\\site-packages\\requests\\sessions.py\", line 530, in request\n",
      "    resp = self.send(prep, **send_kwargs)\n",
      "  File \"c:\\users\\juan\\appdata\\local\\programs\\python\\python38-32\\lib\\site-packages\\requests\\sessions.py\", line 643, in send\n",
      "    r = adapter.send(request, **kwargs)\n",
      "  File \"c:\\users\\juan\\appdata\\local\\programs\\python\\python38-32\\lib\\site-packages\\requests\\adapters.py\", line 439, in send\n",
      "    resp = conn.urlopen(\n",
      "  File \"c:\\users\\juan\\appdata\\local\\programs\\python\\python38-32\\lib\\site-packages\\urllib3\\connectionpool.py\", line 670, in urlopen\n",
      "    httplib_response = self._make_request(\n",
      "  File \"c:\\users\\juan\\appdata\\local\\programs\\python\\python38-32\\lib\\site-packages\\urllib3\\connectionpool.py\", line 426, in _make_request\n",
      "    six.raise_from(e, None)\n",
      "  File \"<string>\", line 3, in raise_from\n",
      "  File \"c:\\users\\juan\\appdata\\local\\programs\\python\\python38-32\\lib\\site-packages\\urllib3\\connectionpool.py\", line 421, in _make_request\n",
      "    httplib_response = conn.getresponse()\n",
      "  File \"c:\\users\\juan\\appdata\\local\\programs\\python\\python38-32\\lib\\http\\client.py\", line 1347, in getresponse\n",
      "    response.begin()\n",
      "  File \"c:\\users\\juan\\appdata\\local\\programs\\python\\python38-32\\lib\\http\\client.py\", line 307, in begin\n",
      "    version, status, reason = self._read_status()\n",
      "  File \"c:\\users\\juan\\appdata\\local\\programs\\python\\python38-32\\lib\\http\\client.py\", line 268, in _read_status\n",
      "    line = str(self.fp.readline(_MAXLINE + 1), \"iso-8859-1\")\n",
      "  File \"c:\\users\\juan\\appdata\\local\\programs\\python\\python38-32\\lib\\socket.py\", line 669, in readinto\n",
      "    return self._sock.recv_into(b)\n",
      "  File \"c:\\users\\juan\\appdata\\local\\programs\\python\\python38-32\\lib\\ssl.py\", line 1241, in recv_into\n",
      "    return self.read(nbytes, buffer)\n",
      "  File \"c:\\users\\juan\\appdata\\local\\programs\\python\\python38-32\\lib\\ssl.py\", line 1099, in read\n",
      "    return self._sslobj.read(len, buffer)\n",
      "KeyboardInterrupt\n",
      "\n",
      "During handling of the above exception, another exception occurred:\n",
      "\n",
      "Traceback (most recent call last):\n",
      "  File \"c:\\users\\juan\\appdata\\local\\programs\\python\\python38-32\\lib\\site-packages\\IPython\\core\\interactiveshell.py\", line 2044, in showtraceback\n",
      "    stb = value._render_traceback_()\n",
      "AttributeError: 'KeyboardInterrupt' object has no attribute '_render_traceback_'\n",
      "\n",
      "During handling of the above exception, another exception occurred:\n",
      "\n",
      "Traceback (most recent call last):\n",
      "  File \"c:\\users\\juan\\appdata\\local\\programs\\python\\python38-32\\lib\\site-packages\\IPython\\core\\interactiveshell.py\", line 3337, in run_ast_nodes\n",
      "    if (await self.run_code(code, result,  async_=asy)):\n",
      "  File \"c:\\users\\juan\\appdata\\local\\programs\\python\\python38-32\\lib\\site-packages\\IPython\\core\\interactiveshell.py\", line 3434, in run_code\n",
      "    self.showtraceback(running_compiled_code=True)\n",
      "  File \"c:\\users\\juan\\appdata\\local\\programs\\python\\python38-32\\lib\\site-packages\\IPython\\core\\interactiveshell.py\", line 2046, in showtraceback\n",
      "    stb = self.InteractiveTB.structured_traceback(etype,\n",
      "  File \"c:\\users\\juan\\appdata\\local\\programs\\python\\python38-32\\lib\\site-packages\\IPython\\core\\ultratb.py\", line 1435, in structured_traceback\n",
      "    return FormattedTB.structured_traceback(\n",
      "  File \"c:\\users\\juan\\appdata\\local\\programs\\python\\python38-32\\lib\\site-packages\\IPython\\core\\ultratb.py\", line 1335, in structured_traceback\n",
      "    return VerboseTB.structured_traceback(\n",
      "  File \"c:\\users\\juan\\appdata\\local\\programs\\python\\python38-32\\lib\\site-packages\\IPython\\core\\ultratb.py\", line 1192, in structured_traceback\n",
      "    formatted_exception = self.format_exception_as_a_whole(etype, evalue, etb, number_of_lines_of_context,\n",
      "  File \"c:\\users\\juan\\appdata\\local\\programs\\python\\python38-32\\lib\\site-packages\\IPython\\core\\ultratb.py\", line 1150, in format_exception_as_a_whole\n",
      "    last_unique, recursion_repeat = find_recursion(orig_etype, evalue, records)\n",
      "  File \"c:\\users\\juan\\appdata\\local\\programs\\python\\python38-32\\lib\\site-packages\\IPython\\core\\ultratb.py\", line 451, in find_recursion\n",
      "    return len(records), 0\n",
      "TypeError: object of type 'NoneType' has no len()\n",
      "\n",
      "During handling of the above exception, another exception occurred:\n",
      "\n",
      "Traceback (most recent call last):\n",
      "  File \"c:\\users\\juan\\appdata\\local\\programs\\python\\python38-32\\lib\\site-packages\\IPython\\core\\interactiveshell.py\", line 2044, in showtraceback\n",
      "    stb = value._render_traceback_()\n",
      "AttributeError: 'TypeError' object has no attribute '_render_traceback_'\n",
      "\n",
      "During handling of the above exception, another exception occurred:\n",
      "\n",
      "Traceback (most recent call last):\n",
      "  File \"c:\\users\\juan\\appdata\\local\\programs\\python\\python38-32\\lib\\site-packages\\IPython\\core\\interactiveshell.py\", line 2922, in _run_cell\n",
      "    return runner(coro)\n",
      "  File \"c:\\users\\juan\\appdata\\local\\programs\\python\\python38-32\\lib\\site-packages\\IPython\\core\\async_helpers.py\", line 68, in _pseudo_sync_runner\n",
      "    coro.send(None)\n",
      "  File \"c:\\users\\juan\\appdata\\local\\programs\\python\\python38-32\\lib\\site-packages\\IPython\\core\\interactiveshell.py\", line 3145, in run_cell_async\n",
      "    has_raised = await self.run_ast_nodes(code_ast.body, cell_name,\n",
      "  File \"c:\\users\\juan\\appdata\\local\\programs\\python\\python38-32\\lib\\site-packages\\IPython\\core\\interactiveshell.py\", line 3356, in run_ast_nodes\n",
      "    self.showtraceback()\n",
      "  File \"c:\\users\\juan\\appdata\\local\\programs\\python\\python38-32\\lib\\site-packages\\IPython\\core\\interactiveshell.py\", line 2046, in showtraceback\n",
      "    stb = self.InteractiveTB.structured_traceback(etype,\n",
      "  File \"c:\\users\\juan\\appdata\\local\\programs\\python\\python38-32\\lib\\site-packages\\IPython\\core\\ultratb.py\", line 1435, in structured_traceback\n",
      "    return FormattedTB.structured_traceback(\n",
      "  File \"c:\\users\\juan\\appdata\\local\\programs\\python\\python38-32\\lib\\site-packages\\IPython\\core\\ultratb.py\", line 1335, in structured_traceback\n",
      "    return VerboseTB.structured_traceback(\n",
      "  File \"c:\\users\\juan\\appdata\\local\\programs\\python\\python38-32\\lib\\site-packages\\IPython\\core\\ultratb.py\", line 1210, in structured_traceback\n",
      "    formatted_exceptions += self.format_exception_as_a_whole(etype, evalue, etb, lines_of_context,\n",
      "  File \"c:\\users\\juan\\appdata\\local\\programs\\python\\python38-32\\lib\\site-packages\\IPython\\core\\ultratb.py\", line 1150, in format_exception_as_a_whole\n",
      "    last_unique, recursion_repeat = find_recursion(orig_etype, evalue, records)\n",
      "  File \"c:\\users\\juan\\appdata\\local\\programs\\python\\python38-32\\lib\\site-packages\\IPython\\core\\ultratb.py\", line 451, in find_recursion\n",
      "    return len(records), 0\n",
      "TypeError: object of type 'NoneType' has no len()\n",
      "\n",
      "During handling of the above exception, another exception occurred:\n",
      "\n",
      "Traceback (most recent call last):\n",
      "  File \"c:\\users\\juan\\appdata\\local\\programs\\python\\python38-32\\lib\\site-packages\\IPython\\core\\interactiveshell.py\", line 2044, in showtraceback\n",
      "    stb = value._render_traceback_()\n",
      "AttributeError: 'TypeError' object has no attribute '_render_traceback_'\n",
      "\n",
      "During handling of the above exception, another exception occurred:\n",
      "\n",
      "Traceback (most recent call last):\n",
      "  File \"c:\\users\\juan\\appdata\\local\\programs\\python\\python38-32\\lib\\site-packages\\IPython\\core\\ultratb.py\", line 1169, in get_records\n",
      "    return _fixed_getinnerframes(etb, number_of_lines_of_context, tb_offset)\n",
      "  File \"c:\\users\\juan\\appdata\\local\\programs\\python\\python38-32\\lib\\site-packages\\IPython\\core\\ultratb.py\", line 316, in wrapped\n",
      "    return f(*args, **kwargs)\n",
      "  File \"c:\\users\\juan\\appdata\\local\\programs\\python\\python38-32\\lib\\site-packages\\IPython\\core\\ultratb.py\", line 350, in _fixed_getinnerframes\n",
      "    records = fix_frame_records_filenames(inspect.getinnerframes(etb, context))\n",
      "  File \"c:\\users\\juan\\appdata\\local\\programs\\python\\python38-32\\lib\\inspect.py\", line 1503, in getinnerframes\n",
      "    frameinfo = (tb.tb_frame,) + getframeinfo(tb, context)\n",
      "  File \"c:\\users\\juan\\appdata\\local\\programs\\python\\python38-32\\lib\\inspect.py\", line 1461, in getframeinfo\n",
      "    filename = getsourcefile(frame) or getfile(frame)\n",
      "  File \"c:\\users\\juan\\appdata\\local\\programs\\python\\python38-32\\lib\\inspect.py\", line 708, in getsourcefile\n",
      "    if getattr(getmodule(object, filename), '__loader__', None) is not None:\n",
      "  File \"c:\\users\\juan\\appdata\\local\\programs\\python\\python38-32\\lib\\inspect.py\", line 754, in getmodule\n",
      "    os.path.realpath(f)] = module.__name__\n",
      "  File \"c:\\users\\juan\\appdata\\local\\programs\\python\\python38-32\\lib\\ntpath.py\", line 664, in realpath\n",
      "    if _getfinalpathname(spath) == path:\n",
      "KeyboardInterrupt\n"
     ]
    }
   ],
   "source": [
    "tmp_df = dff.create_dataset(file_name = 'data/ColombianData.csv')"
   ]
  },
  {
   "cell_type": "code",
   "execution_count": 7,
   "metadata": {},
   "outputs": [
    {
     "data": {
      "text/plain": [
       "[0, 50, 100, 150, 200, 250, 300, 350, 400, 450, 500, 550, 600, 650, 700, 750]"
      ]
     },
     "execution_count": 7,
     "metadata": {},
     "output_type": "execute_result"
    }
   ],
   "source": [
    "list(range(0, 780, 50))"
   ]
  },
  {
   "cell_type": "code",
   "execution_count": 8,
   "metadata": {},
   "outputs": [],
   "source": [
    "def a(idx):\n",
    "    pass"
   ]
  },
  {
   "cell_type": "code",
   "execution_count": 9,
   "metadata": {},
   "outputs": [
    {
     "data": {
      "text/plain": [
       "[None, None, None, None, None, None, None, None, None, None]"
      ]
     },
     "execution_count": 9,
     "metadata": {},
     "output_type": "execute_result"
    }
   ],
   "source": [
    "[a(x) for x in range(10)]"
   ]
  },
  {
   "cell_type": "code",
   "execution_count": null,
   "metadata": {},
   "outputs": [],
   "source": []
  }
 ],
 "metadata": {
  "kernelspec": {
   "display_name": "Python 3",
   "language": "python",
   "name": "python3"
  },
  "language_info": {
   "codemirror_mode": {
    "name": "ipython",
    "version": 3
   },
   "file_extension": ".py",
   "mimetype": "text/x-python",
   "name": "python",
   "nbconvert_exporter": "python",
   "pygments_lexer": "ipython3",
   "version": "3.8.5"
  }
 },
 "nbformat": 4,
 "nbformat_minor": 4
}
